Workbook
Name Slicer_Child_Adult: #N/A
Name Slicer_Pclass: #N/A
Name Slicer_Rounded_Age: #N/A
Name Slicer_Rounded_Fare: #N/A
Name Slicer_Sex: #N/A
Name Slicer_Surname: #N/A
Name Slicer_Survived: #N/A

Sheet Advertising
A1: TV | B1: radio | C1: newspaper | D1: sales | F1: SUMMARY OUTPUT
A2: 230.1 | B2: 37.8 | C2: 69.2 | D2: 22.1
A3: 44.5 | B3: 39.3 | C3: 45.1 | D3: 10.4 | F3: Regression Statistics
A4: 17.2 | B4: 45.9 | C4: 69.3 | D4: 9.3 | F4: Multiple R | G4: 0.94721203
A5: 151.5 | B5: 41.3 | C5: 58.5 | D5: 18.5 | F5: R Square | G5: 0.89721064
A6: 180.8 | B6: 10.8 | C6: 58.4 | D6: 12.9 | F6: Adjusted R Square | G6: 0.89563733
A7: 8.7 | B7: 48.9 | C7: 75 | D7: 7.2 | F7: Standard Error | G7: 1.6855104 | I7: The standard deviation of an estimate is called the standard error. The standard error of the coefficient measures how precisely the model estimates the coefficient's unknown value. The standard error of the coefficient is always positive.
A8: 57.5 | B8: 32.8 | C8: 23.5 | D8: 11.8 | F8: Observations | G8: 200 | I8: Standard Error is a goodness-of-fit measure that shows the precision of your regression analysis - the smaller the number, the more certain you can be about your regression equation. While R2 represents the percentage of the dependent variables variance that is explained by the model, Standard Error is an absolute measure that shows the average distance that the data points fall from the regression line.
A9: 120.2 | B9: 19.6 | C9: 11.6 | D9: 13.2
A10: 8.6 | B10: 2.1 | C10: 1 | D10: 4.8 | F10: ANOVA | G10: https://www.freecodecamp.org/news/https-medium-com-sharadvm-how-to-read-a-regression-table-661d391e9bd7-708e75efc560/
A11: 199.8 | B11: 2.6 | C11: 21.2 | D11: 10.6 | G11: df | H11: SS | I11: MS | J11: F | K11: Significance F | M11: SS Regression explains variability
A12: 66.1 | B12: 5.8 | C12: 24.2 | D12: 8.6 | F12: Regression | G12: 3 | H12: 4860.3235 | I12: 1620.1078 | J12: 570.2707 | K12: 1.5752273e-96 | M12: =H12/H14 -> 0.89721064
A13: 214.7 | B13: 24 | C13: 4 | D13: 17.4 | F13: Residual | G13: 196 | H13: 556.82526 | I13: 2.8409452
A14: 23.8 | B14: 35.1 | C14: 65.9 | D14: 9.2 | F14: Total | G14: 199 | H14: 5417.1487 | M14: Significance relationship between dependent and independent variables
A15: 97.5 | B15: 7.6 | C15: 7.2 | D15: 9.7 | G15: Regression SS | H15: (yhat - ymean)^2 | I15: (yhat-ymean)^2/reg.df | K15: MS between | L15: F Score | M15: F Significance
A16: 204.1 | B16: 32.9 | C16: 46 | D16: 19 | G16: Residual SS | H16: (y - yhat)^2 | I16: (y-yhat)^2/res.df | K16: MS within | L16: =I12/I13 -> 570.2707 | M16: =_xlfn.F.DIST.RT(J12, G12, G13) -> 1.5752273e-96
A17: 195.4 | B17: 47.7 | C17: 52.9 | D17: 22.4
A18: 67.8 | B18: 36.6 | C18: 114 | D18: 12.5 | G18: Coefficients | H18: Standard Error | I18: t Stat | J18: P-value | K18: Lower 95% | L18: Upper 95% | M18: Lower 95.0% | N18: Upper 95.0%
A19: 281.4 | B19: 39.6 | C19: 55.8 | D19: 24.4 | F19: Intercept | G19: 2.9388894 | H19: 0.31190824 | I19: 9.4222884 | J19: 1.2672945e-17 | K19: 2.3237623 | L19: 3.5540165 | M19: 2.3237623 | N19: 3.5540165
A20: 69.2 | B20: 20.5 | C20: 18.3 | D20: 11.3 | F20: TV | G20: 0.045764645 | H20: 0.0013948968 | I20: 32.808624 | J20: 1.50996e-81 | K20: 0.043013712 | L20: 0.048515579 | M20: 0.043013712 | N20: 0.048515579
A21: 147.3 | B21: 23.9 | C21: 19.1 | D21: 14.6 | F21: radio | G21: 0.18853002 | H21: 0.008611234 | I21: 21.893496 | J21: 1.5053389e-54 | K21: 0.17154745 | L21: 0.20551259 | M21: 0.17154745 | N21: 0.20551259
A22: 218.4 | B22: 27.7 | C22: 53.4 | D22: 18 | F22: newspaper | G22: -0.001037493 | H22: 0.0058710096 | I22: -0.17671459 | J22: 0.85991505 | K22: -0.012615953 | L22: 0.010540967 | M22: -0.012615953 | N22: 0.010540967
A23: 237.4 | B23: 5.1 | C23: 23.5 | D23: 12.5 | G23: UCI | H23: T Stat | I23: P-value | L23: Interpreting a coefficient: $1000 dollars on radio advertising would be associated with an increase of sales by 0.19 * 1000, or 190 units, given spending stays the same.
A24: 13.2 | B24: 15.9 | C24: 49.6 | D24: 5.6 | G24: =G20+H20*2 -> 0.048554439 | H24: =G20/H20 -> 32.808624 | I24: =TDIST(I20, 196, 2) -> 1.50996e-81
A25: 228.3 | B25: 16.9 | C25: 26.2 | D25: 15.5 | I25: (t Stat, df, tail) | J25: scipy. stats. t. sf(abs(t stat), df=df)
A26: 62.3 | B26: 12.6 | C26: 18.3 | D26: 9.7 | F26: RESIDUAL OUTPUT | J26: survival function or 1 - cdf
A27: 262.9 | B27: 3.5 | C27: 19.5 | D27: 12
A28: 142.9 | B28: 29.3 | C28: 12.6 | D28: 15 | F28: Observation | G28: Predicted sales | H28: Residuals
A29: 240.1 | B29: 16.7 | C29: 22.9 | D29: 15.9 | F29: 1 | G29: 20.523974 | H29: 1.5760256
A30: 248.8 | B30: 27.1 | C30: 22.9 | D30: 18.9 | F30: 2 | G30: 12.337855 | H30: -1.9378548
A31: 70.6 | B31: 16 | C31: 40.8 | D31: 10.5 | F31: 3 | G31: 12.307671 | H31: -3.0076708
A32: 292.9 | B32: 28.3 | C32: 43.2 | D32: 21.4 | F32: 4 | G32: 17.59783 | H32: 0.90217049
A33: 112.9 | B33: 17.4 | C33: 38.6 | D33: 11.9 | F33: 5 | G33: 13.188672 | H33: -0.28867186
A34: 97.2 | B34: 1.5 | C34: 30 | D34: 9.6 | F34: 6 | G34: 12.478348 | H34: -5.2783476
A35: 265.6 | B35: 20 | C35: 0.3 | D35: 17.4 | F35: 7 | G35: 11.72976 | H35: 0.070240048
A36: 95.7 | B36: 1.4 | C36: 7.4 | D36: 9.5 | F36: 8 | G36: 12.122953 | H36: 1.0770468
A37: 290.7 | B37: 4.1 | C37: 8.5 | D37: 12.8 | F37: 9 | G37: 3.7273409 | H37: 1.0726591 | K37: A residual value is a measure of how much a regression line vertically misses a data point. Regression lines are the best fit of a set of data.
A38: 266.9 | B38: 43.8 | C38: 5 | D38: 25.4 | F38: 10 | G38: 12.550849 | H38: -1.9508487 | K38: Confidence intervals tend to be wider the more variability in a distribution. Confidence intervals tend to be narrower the larger the sample size is. Confidence intervals tend to be narrower when our accuracy is higher.
A39: 74.7 | B39: 49.4 | C39: 45.7 | D39: 14.7 | F39: 11 | G39: 7.0322992 | H39: 1.5677008
A40: 43.1 | B40: 26.7 | C40: 35.1 | D40: 10.1 | F40: 12 | G40: 17.285129 | H40: 0.11487082
...

Sheet Titanic
A1: Index | B1: Survived | C1: Name | D1: Sex | E1: Age | F1: Siblings/Spouses Aboard | G1: Parents/Children Aboard | H1: Pclass | I1: Fare | M1: https://www.statology.org/logistic-regression-excel/
A2: 1 | B2: 0 | C2: Mr. Owen Harris Braund | D2: male | E2: 22 | F2: 1 | G2: 0 | H2: 3 | I2: 7.25 | M2: https://medium.com/@adaoraogbonna/analyses-of-the-titanic-dataset-using-excel-8d1d63d0b177
A3: 2 | B3: 1 | C3: Mrs. John Bradley (Florence Briggs Thayer) Cumings | D3: female | E3: 38 | F3: 1 | G3: 0 | H3: 1 | I3: 71.2833 | M3: https://support.microsoft.com/en-gb/office/create-and-share-a-dashboard-with-excel-and-microsoft-groups-ad92a34d-38d0-4fdd-b8b1-58379aae746e
A4: 3 | B4: 1 | C4: Miss. Laina Heikkinen | D4: female | E4: 26 | F4: 0 | G4: 0 | H4: 3 | I4: 7.925
A5: 4 | B5: 1 | C5: Mrs. Jacques Heath (Lily May Peel) Futrelle | D5: female | E5: 35 | F5: 1 | G5: 0 | H5: 1 | I5: 53.1
A6: 5 | B6: 0 | C6: Mr. William Henry Allen | D6: male | E6: 35 | F6: 0 | G6: 0 | H6: 3 | I6: 8.05
A7: 6 | B7: 0 | C7: Mr. James Moran | D7: male | E7: 27 | F7: 0 | G7: 0 | H7: 3 | I7: 8.4583
A8: 7 | B8: 0 | C8: Mr. Timothy J McCarthy | D8: male | E8: 54 | F8: 0 | G8: 0 | H8: 1 | I8: 51.8625
A9: 8 | B9: 0 | C9: Master. Gosta Leonard Palsson | D9: male | E9: 2 | F9: 3 | G9: 1 | H9: 3 | I9: 21.075
A10: 9 | B10: 1 | C10: Mrs. Oscar W (Elisabeth Vilhelmina Berg) Johnson | D10: female | E10: 27 | F10: 0 | G10: 2 | H10: 3 | I10: 11.1333
A11: 10 | B11: 1 | C11: Mrs. Nicholas (Adele Achem) Nasser | D11: female | E11: 14 | F11: 1 | G11: 0 | H11: 2 | I11: 30.0708
A12: 11 | B12: 1 | C12: Miss. Marguerite Rut Sandstrom | D12: female | E12: 4 | F12: 1 | G12: 1 | H12: 3 | I12: 16.7
A13: 12 | B13: 1 | C13: Miss. Elizabeth Bonnell | D13: female | E13: 58 | F13: 0 | G13: 0 | H13: 1 | I13: 26.55
A14: 13 | B14: 0 | C14: Mr. William Henry Saundercock | D14: male | E14: 20 | F14: 0 | G14: 0 | H14: 3 | I14: 8.05
A15: 14 | B15: 0 | C15: Mr. Anders Johan Andersson | D15: male | E15: 39 | F15: 1 | G15: 5 | H15: 3 | I15: 31.275
... A888: 887 | B888: 0 | C888: Mr. Patrick Dooley | D888: male | E888: 32 | F888: 0 | G888: 0 | H888: 3 | I888: 7.75

Sheet Preprocessing
A1: Index | B1: Survived | C1: Survived Text | D1: Surname | E1: Name | F1: Sex | G1: Age | H1: Siblings/Spouses Aboard | I1: Parents/Children Aboard | J1: Pclass | K1: Fare | L1: SexNum | M1: Rounded Age | N1: Child Adult | O1: Rounded Fare | Q1: https://www.statology.org/logistic-regression-excel/
A2: 1 | B2: 0 | C2: =IF(B2=0,"No","Yes") -> No | D2: Mr | E2: Owen Harris Braund | F2: {=IF(OR(COUNTIF(D2,"*"&$T$9:$T$15&"*")),"Female","Male")} -> Male | G2: 22 | H2: 1 | I2: 0 | J2: 3 | K2: 7.25 | L2: =IF(F2 = "Male", 0, 1) -> 0 | M2: =ROUND(G2, 0) -> 22 | N2: =IF(G2<=16,"Child","Adult") -> Adult | O2: =ROUND(K2, 2) -> 7.25 | Q2: https://medium.com/@adaoraogbonna/analyses-of-the-titanic-dataset-using-excel-8d1d63d0b177
A3: 2 | B3: 1 | C3: =IF(B3=0,"No","Yes") -> Yes | D3: Mrs | E3: John Bradley (Florence Briggs Thayer) Cumings | F3: {=IF(OR(COUNTIF(D3,"*"&$T$9:$T$15&"*")),"Female","Male")} -> Female | G3: 38 | H3: 1 | I3: 0 | J3: 1 | K3: 71.2833 | L3: =IF(F3 = "Male", 0, 1) -> 1 | M3: =ROUND(G3, 0) -> 38 | N3: =IF(G3<=16,"Child","Adult") -> Adult | O3: =ROUND(K3, 2) -> 71.28 | Q3: https://support.microsoft.com/en-gb/office/create-and-share-a-dashboard-with-excel-and-microsoft-groups-ad92a34d-38d0-4fdd-b8b1-58379aae746e
A4: 3 | B4: 1 | C4: =IF(B4=0,"No","Yes") -> Yes | D4: Miss | E4: Laina Heikkinen | F4: {=IF(OR(COUNTIF(D4,"*"&$T$9:$T$15&"*")),"Female","Male")} -> Female | G4: 26 | H4: 0 | I4: 0 | J4: 3 | K4: 7.925 | L4: =IF(F4 = "Male", 0, 1) -> 1 | M4: =ROUND(G4, 0) -> 26 | N4: =IF(G4<=16,"Child","Adult") -> Adult | O4: =ROUND(K4, 2) -> 7.93
A5: 4 | B5: 1 | C5: =IF(B5=0,"No","Yes") -> Yes | D5: Mrs | E5: Jacques Heath (Lily May Peel) Futrelle | F5: {=IF(OR(COUNTIF(D5,"*"&$T$9:$T$15&"*")),"Female","Male")} -> Female | G5: 35 | H5: 1 | I5: 0 | J5: 1 | K5: 53.1 | L5: =IF(F5 = "Male", 0, 1) -> 1 | M5: =ROUND(G5, 0) -> 35 | N5: =IF(G5<=16,"Child","Adult") -> Adult | O5: =ROUND(K5, 2) -> 53.1 | Q5: Highlight name column and use text to column delimiting on , and .
A6: 5 | B6: 0 | C6: =IF(B6=0,"No","Yes") -> No | D6: Mr | E6: William Henry Allen | F6: {=IF(OR(COUNTIF(D6,"*"&$T$9:$T$15&"*")),"Female","Male")} -> Male | G6: 35 | H6: 0 | I6: 0 | J6: 3 | K6: 8.05 | L6: =IF(F6 = "Male", 0, 1) -> 0 | M6: =ROUND(G6, 0) -> 35 | N6: =IF(G6<=16,"Child","Adult") -> Adult | O6: =ROUND(K6, 2) -> 8.05
A7: 6 | B7: 0 | C7: =IF(B7=0,"No","Yes") -> No | D7: Mr | E7: James Moran | F7: {=IF(OR(COUNTIF(D7,"*"&$T$9:$T$15&"*")),"Female","Male")} -> Male | G7: 27 | H7: 0 | I7: 0 | J7: 3 | K7: 8.4583 | L7: =IF(F7 = "Male", 0, 1) -> 0 | M7: =ROUND(G7, 0) -> 27 | N7: =IF(G7<=16,"Child","Adult") -> Adult | O7: =ROUND(K7, 2) -> 8.46
A8: 7 | B8: 0 | C8: =IF(B8=0,"No","Yes") -> No | D8: Mr | E8: Timothy J McCarthy | F8: {=IF(OR(COUNTIF(D8,"*"&$T$9:$T$15&"*")),"Female","Male")} -> Male | G8: 54 | H8: 0 | I8: 0 | J8: 1 | K8: 51.8625 | L8: =IF(F8 = "Male", 0, 1) -> 0 | M8: =ROUND(G8, 0) -> 54 | N8: =IF(G8<=16,"Child","Adult") -> Adult | O8: =ROUND(K8, 2) -> 51.86 | Q8: Unique Surnames: | T8: Femal Surnames | W8: Fill Function Down
A9: 8 | B9: 0 | C9: =IF(B9=0,"No","Yes") -> No | D9: Master | E9: Gosta Leonard Palsson | F9: {=IF(OR(COUNTIF(D9,"*"&$T$9:$T$15&"*")),"Female","Male")} -> Male | G9: 2 | H9: 3 | I9: 1 | J9: 3 | K9: 21.075 | L9: =IF(F9 = "Male", 0, 1) -> 0 | M9: =ROUND(G9, 0) -> 2 | N9: =IF(G9<=16,"Child","Adult") -> Child | O9: =ROUND(K9, 2) -> 21.08 | Q9: {=_xlfn.UNIQUE(D2:D888)} -> Mr | T9: Mrs | W9: Dbl Click Fill Box
A10: 9 | B10: 1 | C10: =IF(B10=0,"No","Yes") -> Yes | D10: Mrs | E10: Oscar W (Elisabeth Vilhelmina Berg) Johnson | F10: {=IF(OR(COUNTIF(D10,"*"&$T$9:$T$15&"*")),"Female","Male")} -> Female | G10: 27 | H10: 0 | I10: 2 | J10: 3 | K10: 11.1333 | L10: =IF(F10 = "Male", 0, 1) -> 1 | M10: =ROUND(G10, 0) -> 27 | N10: =IF(G10<=16,"Child","Adult") -> Adult | O10: =ROUND(K10, 2) -> 11.13 | Q10: Mrs | T10: Miss
A11: 10 | B11: 1 | C11: =IF(B11=0,"No","Yes") -> Yes | D11: Mrs | E11: Nicholas (Adele Achem) Nasser | F11: {=IF(OR(COUNTIF(D11,"*"&$T$9:$T$15&"*")),"Female","Male")} -> Female | G11: 14 | H11: 1 | I11: 0 | J11: 2 | K11: 30.0708 | L11: =IF(F11 = "Male", 0, 1) -> 1 | M11: =ROUND(G11, 0) -> 14 | N11: =IF(G11<=16,"Child","Adult") -> Child | O11: =ROUND(K11, 2) -> 30.07 | Q11: Miss | T11: Mme | W11: "=IF(E2 = "Male", 0, 1)"
A12: 11 | B12: 1 | C12: =IF(B12=0,"No","Yes") -> Yes | D12: Miss | E12: Marguerite Rut Sandstrom | F12: {=IF(OR(COUNTIF(D12,"*"&$T$9:$T$15&"*")),"Female","Male")} -> Female | G12: 4 | H12: 1 | I12: 1 | J12: 3 | K12: 16.7 | L12: =IF(F12 = "Male", 0, 1) -> 1 | M12: =ROUND(G12, 0) -> 4 | N12: =IF(G12<=16,"Child","Adult") -> Child | O12: =ROUND(K12, 2) -> 16.7 | Q12: Master | T12: Ms
A13: 12 | B13: 1 | C13: =IF(B13=0,"No","Yes") -> Yes | D13: Miss | E13: Elizabeth Bonnell | F13: {=IF(OR(COUNTIF(D13,"*"&$T$9:$T$15&"*")),"Female","Male")} -> Female | G13: 58 | H13: 0 | I13: 0 | J13: 1 | K13: 26.55 | L13: =IF(F13 = "Male", 0, 1) -> 1 | M13: =ROUND(G13, 0) -> 58 | N13: =IF(G13<=16,"Child","Adult") -> Adult | O13: =ROUND(K13, 2) -> 26.55 | Q13: Don | T13: Lady
A14: 13 | B14: 0 | C14: =IF(B14=0,"No","Yes") -> No | D14: Mr | E14: William Henry Saundercock | F14: {=IF(OR(COUNTIF(D14,"*"&$T$9:$T$15&"*")),"Female","Male")} -> Male | G14: 20 | H14: 0 | I14: 0 | J14: 3 | K14: 8.05 | L14: =IF(F14 = "Male", 0, 1) -> 0 | M14: =ROUND(G14, 0) -> 20 | N14: =IF(G14<=16,"Child","Adult") -> Adult | O14: =ROUND(K14, 2) -> 8.05 | Q14: Rev | T14: Mlle
A15: 14 | B15: 0 | C15: =IF(B15=0,"No","Yes") -> No | D15: Mr | E15: Anders Johan Andersson | F15: {=IF(OR(COUNTIF(D15,"*"&$T$9:$T$15&"*")),"Female","Male")} -> Male | G15: 39 | H15: 1 | I15: 5 | J15: 3 | K15: 31.275 | L15: =IF(F15 = "Male", 0, 1) -> 0 | M15: =ROUND(G15, 0) -> 39 | N15: =IF(G15<=16,"Child","Adult") -> Adult | O15: =ROUND(K15, 2) -> 31.28 | Q15: Dr | T15: the Countess
A16: 15 | B16: 0 | C16: =IF(B16=0,"No","Yes") -> No | D16: Miss | E16: Hulda Amanda Adolfina Vestrom | F16: {=IF(OR(COUNTIF(D16,"*"&$T$9:$T$15&"*")),"Female","Male")} -> Female | G16: 14 | H16: 0 | I16: 0 | J16: 3 | K16: 7.8542 | L16: =IF(F16 = "Male", 0, 1) -> 1 | M16: =ROUND(G16, 0) -> 14 | N16: =IF(G16<=16,"Child","Adult") -> Child | O16: =ROUND(K16, 2) -> 7.85 | Q16: Mme
A17: 16 | B17: 1 | C17: =IF(B17=0,"No","Yes") -> Yes | D17: Mrs | E17: (Mary D Kingcome) Hewlett | F17: {=IF(OR(COUNTIF(D17,"*"&$T$9:$T$15&"*")),"Female","Male")} -> Female | G17: 55 | H17: 0 | I17: 0 | J17: 2 | K17: 16 | L17: =IF(F17 = "Male", 0, 1) -> 1 | M17: =ROUND(G17, 0) -> 55 | N17: =IF(G17<=16,"Child","Adult") -> Adult | O17: =ROUND(K17, 2) -> 16 | Q17: Ms
A18: 17 | B18: 0 | C18: =IF(B18=0,"No","Yes") -> No | D18: Master | E18: Eugene Rice | F18: {=IF(OR(COUNTIF(D18,"*"&$T$9:$T$15&"*")),"Female","Male")} -> Male | G18: 2 | H18: 4 | I18: 1 | J18: 3 | K18: 29.125 | L18: =IF(F18 = "Male", 0, 1) -> 0 | M18: =ROUND(G18, 0) -> 2 | N18: =IF(G18<=16,"Child","Adult") -> Child | O18: =ROUND(K18, 2) -> 29.13 | Q18: Major
A19: 18 | B19: 1 | C19: =IF(B19=0,"No","Yes") -> Yes | D19: Mr | E19: Charles Eugene Williams | F19: {=IF(OR(COUNTIF(D19,"*"&$T$9:$T$15&"*")),"Female","Male")} -> Male | G19: 23 | H19: 0 | I19: 0 | J19: 2 | K19: 13 | L19: =IF(F19 = "Male", 0, 1) -> 0 | M19: =ROUND(G19, 0) -> 23 | N19: =IF(G19<=16,"Child","Adult") -> Adult | O19: =ROUND(K19, 2) -> 13 | Q19: Lady
A20: 19 | B20: 0 | C20: =IF(B20=0,"No","Yes") -> No | D20: Mrs | E20: Julius (Emelia Maria Vandemoortele) Vander Planke | F20: {=IF(OR(COUNTIF(D20,"*"&$T$9:$T$15&"*")),"Female","Male")} -> Female | G20: 31 | H20: 1 | I20: 0 | J20: 3 | K20: 18 | L20: =IF(F20 = "Male", 0, 1) -> 1 | M20: =ROUND(G20, 0) -> 31 | N20: =IF(G20<=16,"Child","Adult") -> Adult | O20: =ROUND(K20, 2) -> 18 | Q20: Sir
A21: 20 | B21: 1 | C21: =IF(B21=0,"No","Yes") -> Yes | D21: Mrs | E21: Fatima Masselmani | F21: {=IF(OR(COUNTIF(D21,"*"&$T$9:$T$15&"*")),"Female","Male")} -> Female | G21: 22 | H21: 0 | I21: 0 | J21: 3 | K21: 7.225 | L21: =IF(F21 = "Male", 0, 1) -> 1 | M21: =ROUND(G21, 0) -> 22 | N21: =IF(G21<=16,"Child","Adult") -> Adult | O21: =ROUND(K21, 2) -> 7.23 | Q21: Mlle
A22: 21 | B22: 0 | C22: =IF(B22=0,"No","Yes") -> No | D22: Mr | E22: Joseph J Fynney | F22: {=IF(OR(COUNTIF(D22,"*"&$T$9:$T$15&"*")),"Female","Male")} -> Male | G22: 35 | H22: 0 | I22: 0 | J22: 2 | K22: 26 | L22: =IF(F22 = "Male", 0, 1) -> 0 | M22: =ROUND(G22, 0) -> 35 | N22: =IF(G22<=16,"Child","Adult") -> Adult | O22: =ROUND(K22, 2) -> 26 | Q22: Col
A23: 22 | B23: 1 | C23: =IF(B23=0,"No","Yes") -> Yes | D23: Mr | E23: Lawrence Beesley | F23: {=IF(OR(COUNTIF(D23,"*"&$T$9:$T$15&"*")),"Female","Male")} -> Male | G23: 34 | H23: 0 | I23: 0 | J23: 2 | K23: 13 | L23: =IF(F23 = "Male", 0, 1) -> 0 | M23: =ROUND(G23, 0) -> 34 | N23: =IF(G23<=16,"Child","Adult") -> Adult | O23: =ROUND(K23, 2) -> 13 | Q23: Capt
A24: 23 | B24: 1 | C24: =IF(B24=0,"No","Yes") -> Yes | D24: Miss | E24: Anna McGowan | F24: {=IF(OR(COUNTIF(D24,"*"&$T$9:$T$15&"*")),"Female","Male")} -> Female | G24: 15 | H24: 0 | I24: 0 | J24: 3 | K24: 8.0292 | L24: =IF(F24 = "Male", 0, 1) -> 1 | M24: =ROUND(G24, 0) -> 15 | N24: =IF(G24<=16,"Child","Adult") -> Child | O24: =ROUND(K24, 2) -> 8.03 | Q24: the Countess
A25: 24 | B25: 1 | C25: =IF(B25=0,"No","Yes") -> Yes | D25: Mr | E25: William Thompson Sloper | F25: {=IF(OR(COUNTIF(D25,"*"&$T$9:$T$15&"*")),"Female","Male")} -> Male | G25: 28 | H25: 0 | I25: 0 | J25: 1 | K25: 35.5 | L25: =IF(F25 = "Male", 0, 1) -> 0 | M25: =ROUND(G25, 0) -> 28 | N25: =IF(G25<=16,"Child","Adult") -> Adult | O25: =ROUND(K25, 2) -> 35.5 | Q25: Jonkheer | S25: Title of nobility
A26: 25 | B26: 0 | C26: =IF(B26=0,"No","Yes") -> No | D26: Miss | E26: Torborg Danira Palsson | F26: {=IF(OR(COUNTIF(D26,"*"&$T$9:$T$15&"*")),"Female","Male")} -> Female | G26: 8 | H26: 3 | I26: 1 | J26: 3 | K26: 21.075 | L26: =IF(F26 = "Male", 0, 1) -> 1 | M26: =ROUND(G26, 0) -> 8 | N26: =IF(G26<=16,"Child","Adult") -> Child | O26: =ROUND(K26, 2) -> 21.08
A27: 26 | B27: 1 | C27: =IF(B27=0,"No","Yes") -> Yes | D27: Mrs | E27: Carl Oscar (Selma Augusta Emilia Johansson) Asplund | F27: {=IF(OR(COUNTIF(D27,"*"&$T$9:$T$15&"*")),"Female","Male")} -> Female | G27: 38 | H27: 1 | I27: 5 | J27: 3 | K27: 31.3875 | L27: =IF(F27 = "Male", 0, 1) -> 1 | M27: =ROUND(G27, 0) -> 38 | N27: =IF(G27<=16,"Child","Adult") -> Adult | O27: =ROUND(K27, 2) -> 31.39
A28: 27 | B28: 0 | C28: =IF(B28=0,"No","Yes") -> No | D28: Mr | E28: Farred Chehab Emir | F28: {=IF(OR(COUNTIF(D28,"*"&$T$9:$T$15&"*")),"Female","Male")} -> Male | G28: 26 | H28: 0 | I28: 0 | J28: 3 | K28: 7.225 | L28: =IF(F28 = "Male", 0, 1) -> 0 | M28: =ROUND(G28, 0) -> 26 | N28: =IF(G28<=16,"Child","Adult") -> Adult | O28: =ROUND(K28, 2) -> 7.23
A29: 28 | B29: 0 | C29: =IF(B29=0,"No","Yes") -> No | D29: Mr | E29: Charles Alexander Fortune | F29: {=IF(OR(COUNTIF(D29,"*"&$T$9:$T$15&"*")),"Female","Male")} -> Male | G29: 19 | H29: 3 | I29: 2 | J29: 1 | K29: 263 | L29: =IF(F29 = "Male", 0, 1) -> 0 | M29: =ROUND(G29, 0) -> 19 | N29: =IF(G29<=16,"Child","Adult") -> Adult | O29: =ROUND(K29, 2) -> 263
A30: 29 | B30: 1 | C30: =IF(B30=0,"No","Yes") -> Yes | D30: Miss | E30: Ellen O'Dwyer | F30: {=IF(OR(COUNTIF(D30,"*"&$T$9:$T$15&"*")),"Female","Male")} -> Female | G30: 24 | H30: 0 | I30: 0 | J30: 3 | K30: 7.8792 | L30: =IF(F30 = "Male", 0, 1) -> 1 | M30: =ROUND(G30, 0) -> 24 | N30: =IF(G30<=16,"Child","Adult") -> Adult | O30: =ROUND(K30, 2) -> 7.88
A31: 30 | B31: 0 | C31: =IF(B31=0,"No","Yes") -> No | D31: Mr | E31: Lalio Todoroff | F31: {=IF(OR(COUNTIF(D31,"*"&$T$9:$T$15&"*")),"Female","Male")} -> Male | G31: 23 | H31: 0 | I31: 0 | J31: 3 | K31: 7.8958 | L31: =IF(F31 = "Male", 0, 1) -> 0 | M31: =ROUND(G31, 0) -> 23 | N31: =IF(G31<=16,"Child","Adult") -> Adult | O31: =ROUND(K31, 2) -> 7.9
A32: 31 | B32: 0 | C32: =IF(B32=0,"No","Yes") -> No | D32: Don | E32: Manuel E Uruchurtu | F32: {=IF(OR(COUNTIF(D32,"*"&$T$9:$T$15&"*")),"Female","Male")} -> Male | G32: 40 | H32: 0 | I32: 0 | J32: 1 | K32: 27.7208 | L32: =IF(F32 = "Male", 0, 1) -> 0 | M32: =ROUND(G32, 0) -> 40 | N32: =IF(G32<=16,"Child","Adult") -> Adult | O32: =ROUND(K32, 2) -> 27.72
A33: 32 | B33: 1 | C33: =IF(B33=0,"No","Yes") -> Yes | D33: Mrs | E33: William Augustus (Marie Eugenie) Spencer | F33: {=IF(OR(COUNTIF(D33,"*"&$T$9:$T$15&"*")),"Female","Male")} -> Female | G33: 48 | H33: 1 | I33: 0 | J33: 1 | K33: 146.5208 | L33: =IF(F33 = "Male", 0, 1) -> 1 | M33: =ROUND(G33, 0) -> 48 | N33: =IF(G33<=16,"Child","Adult") -> Adult | O33: =ROUND(K33, 2) -> 146.52
A34: 33 | B34: 1 | C34: =IF(B34=0,"No","Yes") -> Yes | D34: Miss | E34: Mary Agatha Glynn | F34: {=IF(OR(COUNTIF(D34,"*"&$T$9:$T$15&"*")),"Female","Male")} -> Female | G34: 18 | H34: 0 | I34: 0 | J34: 3 | K34: 7.75 | L34: =IF(F34 = "Male", 0, 1) -> 1 | M34: =ROUND(G34, 0) -> 18 | N34: =IF(G34<=16,"Child","Adult") -> Adult | O34: =ROUND(K34, 2) -> 7.75
A35: 34 | B35: 0 | C35: =IF(B35=0,"No","Yes") -> No | D35: Mr | E35: Edward H Wheadon | F35: {=IF(OR(COUNTIF(D35,"*"&$T$9:$T$15&"*")),"Female","Male")} -> Male | G35: 66 | H35: 0 | I35: 0 | J35: 2 | K35: 10.5 | L35: =IF(F35 = "Male", 0, 1) -> 0 | M35: =ROUND(G35, 0) -> 66 | N35: =IF(G35<=16,"Child","Adult") -> Adult | O35: =ROUND(K35, 2) -> 10.5
A36: 35 | B36: 0 | C36: =IF(B36=0,"No","Yes") -> No | D36: Mr | E36: Edgar Joseph Meyer | F36: {=IF(OR(COUNTIF(D36,"*"&$T$9:$T$15&"*")),"Female","Male")} -> Male | G36: 28 | H36: 1 | I36: 0 | J36: 1 | K36: 82.1708 | L36: =IF(F36 = "Male", 0, 1) -> 0 | M36: =ROUND(G36, 0) -> 28 | N36: =IF(G36<=16,"Child","Adult") -> Adult | O36: =ROUND(K36, 2) -> 82.17
A37: 36 | B37: 0 | C37: =IF(B37=0,"No","Yes") -> No | D37: Mr | E37: Alexander Oskar Holverson | F37: {=IF(OR(COUNTIF(D37,"*"&$T$9:$T$15&"*")),"Female","Male")} -> Male | G37: 42 | H37: 1 | I37: 0 | J37: 1 | K37: 52 | L37: =IF(F37 = "Male", 0, 1) -> 0 | M37: =ROUND(G37, 0) -> 42 | N37: =IF(G37<=16,"Child","Adult") -> Adult | O37: =ROUND(K37, 2) -> 52
... A888: 887 | B888: 0 | C888: =IF(B888=0,"No","Yes") -> No | D888: Mr | E888: Patrick Dooley | F888: {=IF(OR(COUNTIF(D888,"*"&$T$9:$T$15&"*")),"Female","Male")} -> Male | G888: 32 | H888: 0 | I888: 0 | J888: 3 | K888: 7.75 | L888: =IF(F888 = "Male", 0, 1) -> 0 | M888: =ROUND(G888, 0) -> 32 | N888: =IF(G888<=16,"Child","Adult") -> Adult | O888: =ROUND(K888, 2) -> 7.75

Sheet Table
A1: Index | B1: Survived Num | C1: Survived | D1: Surname | E1: Name | F1: Sex | G1: Age | H1: Siblings/Spouses Aboard | I1: Parents/Children Aboard | J1: Pclass | K1: Fare | L1: SexNum | M1: Rounded Age | N1: Child Adult | O1: Rounded Fare
A2: 1 | B2: 0 | C2: =IF(B2=0,"No","Yes") -> No | D2: Mr | E2: Owen Harris Braund | F2: {=IF(OR(COUNTIF(D2,"*"&Preprocessing!$T$9:$T$15&"*")),"Female","Male")} -> Male | G2: 22 | H2: 1 | I2: 0 | J2: 3 | K2: 7.25 | L2: =IF(F2 = "Male", 0, 1) -> 0 | M2: =ROUND(G2, 0) -> 22 | N2: =IF(G2<=16,"Child","Adult") -> Adult | O2: =ROUND(K2, 2) -> 7.25 | Q2: Home Format as Table
A3: 2 | B3: 1 | C3: =IF(B3=0,"No","Yes") -> Yes | D3: Mrs | E3: John Bradley (Florence Briggs Thayer) Cumings | F3: {=IF(OR(COUNTIF(D3,"*"&Preprocessing!$T$9:$T$15&"*")),"Female","Male")} -> Female | G3: 38 | H3: 1 | I3: 0 | J3: 1 | K3: 71.2833 | L3: =IF(F3 = "Male", 0, 1) -> 1 | M3: =ROUND(G3, 0) -> 38 | N3: =IF(G3<=16,"Child","Adult") -> Adult | O3: =ROUND(K3, 2) -> 71.28 | Q3: Insert PivotTable to New Worksheet
A4: 3 | B4: 1 | C4: =IF(B4=0,"No","Yes") -> Yes | D4: Miss | E4: Laina Heikkinen | F4: {=IF(OR(COUNTIF(D4,"*"&Preprocessing!$T$9:$T$15&"*")),"Female","Male")} -> Female | G4: 26 | H4: 0 | I4: 0 | J4: 3 | K4: 7.925 | L4: =IF(F4 = "Male", 0, 1) -> 1 | M4: =ROUND(G4, 0) -> 26 | N4: =IF(G4<=16,"Child","Adult") -> Adult | O4: =ROUND(K4, 2) -> 7.93
A5: 4 | B5: 1 | C5: =IF(B5=0,"No","Yes") -> Yes | D5: Mrs | E5: Jacques Heath (Lily May Peel) Futrelle | F5: {=IF(OR(COUNTIF(D5,"*"&Preprocessing!$T$9:$T$15&"*")),"Female","Male")} -> Female | G5: 35 | H5: 1 | I5: 0 | J5: 1 | K5: 53.1 | L5: =IF(F5 = "Male", 0, 1) -> 1 | M5: =ROUND(G5, 0) -> 35 | N5: =IF(G5<=16,"Child","Adult") -> Adult | O5: =ROUND(K5, 2) -> 53.1 | Q5: =COUNTIF(N:N,"Child") -> 114
A6: 5 | B6: 0 | C6: =IF(B6=0,"No","Yes") -> No | D6: Mr | E6: William Henry Allen | F6: {=IF(OR(COUNTIF(D6,"*"&Preprocessing!$T$9:$T$15&"*")),"Female","Male")} -> Male | G6: 35 | H6: 0 | I6: 0 | J6: 3 | K6: 8.05 | L6: =IF(F6 = "Male", 0, 1) -> 0 | M6: =ROUND(G6, 0) -> 35 | N6: =IF(G6<=16,"Child","Adult") -> Adult | O6: =ROUND(K6, 2) -> 8.05
A7: 6 | B7: 0 | C7: =IF(B7=0,"No","Yes") -> No | D7: Mr | E7: James Moran | F7: {=IF(OR(COUNTIF(D7,"*"&Preprocessing!$T$9:$T$15&"*")),"Female","Male")} -> Male | G7: 27 | H7: 0 | I7: 0 | J7: 3 | K7: 8.4583 | L7: =IF(F7 = "Male", 0, 1) -> 0 | M7: =ROUND(G7, 0) -> 27 | N7: =IF(G7<=16,"Child","Adult") -> Adult | O7: =ROUND(K7, 2) -> 8.46
A8: 7 | B8: 0 | C8: =IF(B8=0,"No","Yes") -> No | D8: Mr | E8: Timothy J McCarthy | F8: {=IF(OR(COUNTIF(D8,"*"&Preprocessing!$T$9:$T$15&"*")),"Female","Male")} -> Male | G8: 54 | H8: 0 | I8: 0 | J8: 1 | K8: 51.8625 | L8: =IF(F8 = "Male", 0, 1) -> 0 | M8: =ROUND(G8, 0) -> 54 | N8: =IF(G8<=16,"Child","Adult") -> Adult | O8: =ROUND(K8, 2) -> 51.86
A9: 8 | B9: 0 | C9: =IF(B9=0,"No","Yes") -> No | D9: Master | E9: Gosta Leonard Palsson | F9: {=IF(OR(COUNTIF(D9,"*"&Preprocessing!$T$9:$T$15&"*")),"Female","Male")} -> Male | G9: 2 | H9: 3 | I9: 1 | J9: 3 | K9: 21.075 | L9: =IF(F9 = "Male", 0, 1) -> 0 | M9: =ROUND(G9, 0) -> 2 | N9: =IF(G9<=16,"Child","Adult") -> Child | O9: =ROUND(K9, 2) -> 21.08
A10: 9 | B10: 1 | C10: =IF(B10=0,"No","Yes") -> Yes | D10: Mrs | E10: Oscar W (Elisabeth Vilhelmina Berg) Johnson | F10: {=IF(OR(COUNTIF(D10,"*"&Preprocessing!$T$9:$T$15&"*")),"Female","Male")} -> Female | G10: 27 | H10: 0 | I10: 2 | J10: 3 | K10: 11.1333 | L10: =IF(F10 = "Male", 0, 1) -> 1 | M10: =ROUND(G10, 0) -> 27 | N10: =IF(G10<=16,"Child","Adult") -> Adult | O10: =ROUND(K10, 2) -> 11.13
A11: 10 | B11: 1 | C11: =IF(B11=0,"No","Yes") -> Yes | D11: Mrs | E11: Nicholas (Adele Achem) Nasser | F11: {=IF(OR(COUNTIF(D11,"*"&Preprocessing!$T$9:$T$15&"*")),"Female","Male")} -> Female | G11: 14 | H11: 1 | I11: 0 | J11: 2 | K11: 30.0708 | L11: =IF(F11 = "Male", 0, 1) -> 1 | M11: =ROUND(G11, 0) -> 14 | N11: =IF(G11<=16,"Child","Adult") -> Child | O11: =ROUND(K11, 2) -> 30.07
A12: 11 | B12: 1 | C12: =IF(B12=0,"No","Yes") -> Yes | D12: Miss | E12: Marguerite Rut Sandstrom | F12: {=IF(OR(COUNTIF(D12,"*"&Preprocessing!$T$9:$T$15&"*")),"Female","Male")} -> Female | G12: 4 | H12: 1 | I12: 1 | J12: 3 | K12: 16.7 | L12: =IF(F12 = "Male", 0, 1) -> 1 | M12: =ROUND(G12, 0) -> 4 | N12: =IF(G12<=16,"Child","Adult") -> Child | O12: =ROUND(K12, 2) -> 16.7
A13: 12 | B13: 1 | C13: =IF(B13=0,"No","Yes") -> Yes | D13: Miss | E13: Elizabeth Bonnell | F13: {=IF(OR(COUNTIF(D13,"*"&Preprocessing!$T$9:$T$15&"*")),"Female","Male")} -> Female | G13: 58 | H13: 0 | I13: 0 | J13: 1 | K13: 26.55 | L13: =IF(F13 = "Male", 0, 1) -> 1 | M13: =ROUND(G13, 0) -> 58 | N13: =IF(G13<=16,"Child","Adult") -> Adult | O13: =ROUND(K13, 2) -> 26.55
A14: 13 | B14: 0 | C14: =IF(B14=0,"No","Yes") -> No | D14: Mr | E14: William Henry Saundercock | F14: {=IF(OR(COUNTIF(D14,"*"&Preprocessing!$T$9:$T$15&"*")),"Female","Male")} -> Male | G14: 20 | H14: 0 | I14: 0 | J14: 3 | K14: 8.05 | L14: =IF(F14 = "Male", 0, 1) -> 0 | M14: =ROUND(G14, 0) -> 20 | N14: =IF(G14<=16,"Child","Adult") -> Adult | O14: =ROUND(K14, 2) -> 8.05
A15: 14 | B15: 0 | C15: =IF(B15=0,"No","Yes") -> No | D15: Mr | E15: Anders Johan Andersson | F15: {=IF(OR(COUNTIF(D15,"*"&Preprocessing!$T$9:$T$15&"*")),"Female","Male")} -> Male | G15: 39 | H15: 1 | I15: 5 | J15: 3 | K15: 31.275 | L15: =IF(F15 = "Male", 0, 1) -> 0 | M15: =ROUND(G15, 0) -> 39 | N15: =IF(G15<=16,"Child","Adult") -> Adult | O15: =ROUND(K15, 2) -> 31.28
A16: 15 | B16: 0 | C16: =IF(B16=0,"No","Yes") -> No | D16: Miss | E16: Hulda Amanda Adolfina Vestrom | F16: {=IF(OR(COUNTIF(D16,"*"&Preprocessing!$T$9:$T$15&"*")),"Female","Male")} -> Female | G16: 14 | H16: 0 | I16: 0 | J16: 3 | K16: 7.8542 | L16: =IF(F16 = "Male", 0, 1) -> 1 | M16: =ROUND(G16, 0) -> 14 | N16: =IF(G16<=16,"Child","Adult") -> Child | O16: =ROUND(K16, 2) -> 7.85
A17: 16 | B17: 1 | C17: =IF(B17=0,"No","Yes") -> Yes | D17: Mrs | E17: (Mary D Kingcome) Hewlett | F17: {=IF(OR(COUNTIF(D17,"*"&Preprocessing!$T$9:$T$15&"*")),"Female","Male")} -> Female | G17: 55 | H17: 0 | I17: 0 | J17: 2 | K17: 16 | L17: =IF(F17 = "Male", 0, 1) -> 1 | M17: =ROUND(G17, 0) -> 55 | N17: =IF(G17<=16,"Child","Adult") -> Adult | O17: =ROUND(K17, 2) -> 16
... A888: 887 | B888: 0 | C888: =IF(B888=0,"No","Yes") -> No | D888: Mr | E888: Patrick Dooley | F888: {=IF(OR(COUNTIF(D888,"*"&Preprocessing!$T$9:$T$15&"*")),"Female","Male")} -> Male | G888: 32 | H888: 0 | I888: 0 | J888: 3 | K888: 7.75 | L888: =IF(F888 = "Male", 0, 1) -> 0 | M888: =ROUND(G888, 0) -> 32 | N888: =IF(G888<=16,"Child","Adult") -> Adult | O888: =ROUND(K888, 2) -> 7.75

Sheet Dashboard
A22: Count of Sex | B22: Column Labels
A23: Row Labels | B23: Female | C23: Male | D23: Grand Total
A24: Adult | B24: 256 | C24: 517 | D24: 773
A25: 1 | B25: 87 | C25: 120 | D25: 207
A26: No | B26: 2 | C26: 77 | D26: 79
A27: Yes | B27: 85 | C27: 43 | D27: 128
A28: 2 | B28: 66 | C28: 97 | D28: 163
A29: No | B29: 6 | C29: 89 | D29: 95
A30: Yes | B30: 60 | C30: 8 | D30: 68
A31: 3 | B31: 103 | C31: 300 | D31: 403
A32: No | B32: 51 | C32: 265 | D32: 316
A33: Yes | B33: 52 | C33: 35 | D33: 87
A34: Child | B34: 57 | C34: 57 | D34: 114
A35: 1 | B35: 6 | C35: 3 | D35: 9
A36: No | B36: 1 | D36: 1
A37: Yes | B37: 5 | C37: 3 | D37: 8
A38: 2 | B38: 10 | C38: 11 | D38: 21
A39: No | C39: 2 | D39: 2
A40: Yes | B40: 10 | C40: 9 | D40: 19
A41: 3 | B41: 41 | C41: 43 | D41: 84
A42: No | B42: 21 | C42: 31 | D42: 52
A43: Yes | B43: 20 | C43: 12 | D43: 32
A44: Grand Total | B44: 313 | C44: 574 | D44: 887
A46: Row Labels | B46: Count of Survived | D46: Row Labels | E46: Count of Survived | G46: Row Labels | H46: Count of Child Adult
A47: No | B47: 545 | D47: No | E47: 545 | G47: Female | H47: 313
A48: Yes | B48: 342 | D48: Female | E48: 81 | G48: Adult | H48: 256
A49: Grand Total | B49: 887 | D49: Male | E49: 464 | G49: Child | H49: 57
D50: Yes | E50: 342 | G50: Male | H50: 574
D51: Female | E51: 232 | G51: Adult | H51: 517
D52: Male | E52: 110 | G52: Child | H52: 57
D53: Grand Total | E53: 887 | G53: Grand Total | H53: 887
